Workbook

Sheet README
A1: AptoHire financial model (5 years, INR)
A3: Purpose: an assumption-driven projection for pitch discussions. It is NOT a forecast backed by customer data.
A4: Status: every blue number is a hypothesis to validate in the pilot. Replace them with measured values as soon as you have them.
A5: How to use: change the yellow scenario cell on 'Assumptions' (1 Conservative, 2 Base, 3 Optimistic) or edit any blue input. All other sheets recalculate.
A6: Colour code: blue = input, black = formula, green = link to another sheet, yellow fill = key lever.
A7: Sheets: Assumptions (inputs) > Customers (volumes) > PnL (revenue, costs, cash) > UnitEconomics > Scenarios (static snapshot).
A8: Currency: Indian rupees (INR). 1 lakh = 100,000. 1 crore = 10,000,000 (100 lakh).
A9: Simplifications: annual periods; customers ramp linearly within a year (average of start and end); working capital, D&A, interest and loss carry-forward are ignored.
A10: Cost flexing: in the Conservative and Optimistic scenarios, hiring (engineers, sales, product, admin) scales by the 'Hiring/cost x' factor; founders and fixed costs do not.
A11: Sources for market context are listed in 07_Market_Research_and_Analysis.md and 08_Competition_Analysis.md in the pitch pack.

Sheet Assumptions
A1: Assumptions (INR)
A2: Blue = input. Yellow = key lever. Edit blue cells only.
A4: Active scenario (1=Conservative, 2=Base, 3=Optimistic) | B4: 2
A6: Scenario table | B6: Customer volume x | C6: Price x | D6: Hiring/cost x
A7: Conservative | B7: 0.5 | C7: 0.9 | D7: 0.6
A8: Base | B8: 1 | C8: 1 | D8: 1
A9: Optimistic | B9: 1.4 | C9: 1.1 | D9: 1.2
A11: Active customer volume x | B11: =INDEX(B7:B9,$B$4) -> 1
A12: Active price x | B12: =INDEX(C7:C9,$B$4) -> 1
A13: Active hiring/cost x | B13: =INDEX(D7:D9,$B$4) -> 1
A15: Input (base case) | B15: Year 1 | C15: Year 2 | D15: Year 3 | E15: Year 4 | F15: Year 5 | G15: Basis / note
A16: Calendar year (launch pilots Q4 2026) | B16: 2027 | C16: 2028 | D16: 2029 | E16: 2030 | F16: 2031
A17: Paying institutions at year-end (base case) | B17: 4 | C17: 25 | D17: 90 | E17: 200 | F17: 420 | G17: Hypothesis. Y1 = pilot-to-paid conversions. Replace with signed pilots/LOIs.
A18: Paying startups/SMEs at year-end (base case) | B18: 6 | C18: 70 | D18: 260 | E18: 600 | F18: 1200 | G18: Hypothesis. DPIIT lists 2.23 lakh recognised startups (31 Mar 2026), so this is a small share.
A19: Paying corporates at year-end (base case) | B19: 1 | C19: 10 | D19: 40 | E19: 100 | F19: 190 | G19: Hypothesis. Seasonal campus-hiring plans.
A20: Institution annual churn | B20: 0.1 | C20: 0.1 | D20: 0.1 | E20: 0.1 | F20: 0.1 | G20: Assumption. Measure from pilot renewals.
A21: Startup/SME annual churn | B21: 0.4 | C21: 0.4 | D21: 0.4 | E21: 0.4 | F21: 0.4 | G21: Assumption. Hiring is episodic, so churn is high.
A22: Corporate annual churn | B22: 0.25 | C22: 0.25 | D22: 0.25 | E22: 0.25 | F22: 0.25 | G22: Assumption.
A23: Institution ARPU (INR per year, realised) | B23: 100000 | C23: 150000 | D23: 180000 | E23: 200000 | F23: 220000 | G23: Hypothesis ('low lakhs per year' in idea doc). Y1 discounted for pilots.
A24: Startup/SME ARPU (INR per year) | B24: 45000 | C24: 45000 | D24: 48000 | E24: 50000 | F24: 55000 | G24: Hypothesis: about 3 job packs at INR 15,000.
A25: Corporate ARPU (INR per year) | B25: 150000 | C25: 300000 | D25: 330000 | E25: 350000 | F25: 400000 | G25: Hypothesis: seasonal campus plan. Y1 discounted.
A26: Programme CAC per new institution (INR) | B26: 50000 | C26: 50000 | D26: 50000 | E26: 50000 | F26: 50000 | G26: Assumption: travel, demos, pilot support. Excludes salaries (counted in People).
A27: Programme CAC per new startup/SME (INR) | B27: 10000 | C27: 10000 | D27: 10000 | E27: 10000 | F27: 10000 | G27: Assumption: outreach, content. Idea doc range for recruiter CAC: INR 18-25K (fully loaded).
A28: Programme CAC per new corporate (INR) | B28: 50000 | C28: 50000 | D28: 50000 | E28: 50000 | F28: 50000 | G28: Assumption.
... A48: Equity funding received (INR) | B48: 30000000 | C48: 0 | D48: 0 | E48: 0 | F48: 0 | G48: PROPOSED ask: INR 3 crore. Illustrative; founders to decide.
A50: Opening cash before funding (INR) | B50: 500000 | G50: Founder capital. Assumption.
A51: Tax rate on positive EBITDA | B51: 0.25 | G51: Simplified: no loss carry-forward, no D&A or interest (conservative).

Sheet Customers
A1: Customer volumes (formulas)
B3: Year 1 | C3: Year 2 | D3: Year 3 | E3: Year 4 | F3: Year 5
A4: Institutions
A5: Start of year | B5: 0 | C5: =B6 -> 4 | D5: =C6 -> 25 | E5: =D6 -> 90 | F5: =E6 -> 200
A6: End of year (scenario-adjusted) | B6: =ROUND(Assumptions!B17*Assumptions!$B$11,0) -> 4 | C6: =ROUND(Assumptions!C17*Assumptions!$B$11,0) -> 25 | D6: =ROUND(Assumptions!D17*Assumptions!$B$11,0) -> 90 | E6: =ROUND(Assumptions!E17*Assumptions!$B$11,0) -> 200 | F6: =ROUND(Assumptions!F17*Assumptions!$B$11,0) -> 420
A7: Churned during year | B7: =ROUND(B5*Assumptions!B20,0) -> 0 | C7: =ROUND(C5*Assumptions!C20,0) -> 0 | D7: =ROUND(D5*Assumptions!D20,0) -> 3 | E7: =ROUND(E5*Assumptions!E20,0) -> 9 | F7: =ROUND(F5*Assumptions!F20,0) -> 20
A8: Gross new customers | B8: =MAX(0,B6-B5+B7) -> 4 | C8: =MAX(0,C6-C5+C7) -> 21 | D8: =MAX(0,D6-D5+D7) -> 68 | E8: =MAX(0,E6-E5+E7) -> 119 | F8: =MAX(0,F6-F5+F7) -> 240
A9: Average paying customers | B9: =(B5+B6)/2 -> 2 | C9: =(C5+C6)/2 -> 14.5 | D9: =(D5+D6)/2 -> 57.5 | E9: =(E5+E6)/2 -> 145 | F9: =(F5+F6)/2 -> 310
A11: Startups/SMEs
A12: Start of year | B12: 0 | C12: =B13 -> 6 | D12: =C13 -> 70 | E12: =D13 -> 260 | F12: =E13 -> 600
A13: End of year (scenario-adjusted) | B13: =ROUND(Assumptions!B18*Assumptions!$B$11,0) -> 6 | C13: =ROUND(Assumptions!C18*Assumptions!$B$11,0) -> 70 | D13: =ROUND(Assumptions!D18*Assumptions!$B$11,0) -> 260 | E13: =ROUND(Assumptions!E18*Assumptions!$B$11,0) -> 600 | F13: =ROUND(Assumptions!F18*Assumptions!$B$11,0) -> 1200
A14: Churned during year | B14: =ROUND(B12*Assumptions!B21,0) -> 0 | C14: =ROUND(C12*Assumptions!C21,0) -> 2 | D14: =ROUND(D12*Assumptions!D21,0) -> 28 | E14: =ROUND(E12*Assumptions!E21,0) -> 104 | F14: =ROUND(F12*Assumptions!F21,0) -> 240
A15: Gross new customers | B15: =MAX(0,B13-B12+B14) -> 6 | C15: =MAX(0,C13-C12+C14) -> 66 | D15: =MAX(0,D13-D12+D14) -> 218 | E15: =MAX(0,E13-E12+E14) -> 444 | F15: =MAX(0,F13-F12+F14) -> 840
A16: Average paying customers | B16: =(B12+B13)/2 -> 3 | C16: =(C12+C13)/2 -> 38 | D16: =(D12+D13)/2 -> 165 | E16: =(E12+E13)/2 -> 430 | F16: =(F12+F13)/2 -> 900
A18: Corporates
A19: Start of year | B19: 0 | C19: =B20 -> 1 | D19: =C20 -> 10 | E19: =D20 -> 40 | F19: =E20 -> 100
A20: End of year (scenario-adjusted) | B20: =ROUND(Assumptions!B19*Assumptions!$B$11,0) -> 1 | C20: =ROUND(Assumptions!C19*Assumptions!$B$11,0) -> 10 | D20: =ROUND(Assumptions!D19*Assumptions!$B$11,0) -> 40 | E20: =ROUND(Assumptions!E19*Assumptions!$B$11,0) -> 100 | F20: =ROUND(Assumptions!F19*Assumptions!$B$11,0) -> 190
A21: Churned during year | B21: =ROUND(B19*Assumptions!B22,0) -> 0 | C21: =ROUND(C19*Assumptions!C22,0) -> 0 | D21: =ROUND(D19*Assumptions!D22,0) -> 3 | E21: =ROUND(E19*Assumptions!E22,0) -> 10 | F21: =ROUND(F19*Assumptions!F22,0) -> 25
A22: Gross new customers | B22: =MAX(0,B20-B19+B21) -> 1 | C22: =MAX(0,C20-C19+C21) -> 9 | D22: =MAX(0,D20-D19+D21) -> 33 | E22: =MAX(0,E20-E19+E21) -> 70 | F22: =MAX(0,F20-F19+F21) -> 115
A23: Average paying customers | B23: =(B19+B20)/2 -> 0.5 | C23: =(C19+C20)/2 -> 5.5 | D23: =(D19+D20)/2 -> 25 | E23: =(E19+E20)/2 -> 70 | F23: =(F19+F20)/2 -> 145
A25: Usage
A26: Active students (end-of-year institutions x students per institution) | B26: =B6*Assumptions!B29 -> 1500 | C26: =C6*Assumptions!C29 -> 15000 | D26: =D6*Assumptions!D29 -> 63000 | E26: =E6*Assumptions!E29 -> 140000 | F26: =F6*Assumptions!F29 -> 294000
A27: Project reviews (students x reviews per student) | B27: =B26*Assumptions!B30 -> 3000 | C27: =C26*Assumptions!C30 -> 37500 | D27: =D26*Assumptions!D30 -> 189000 | E27: =E26*Assumptions!E30 -> 420000 | F27: =F26*Assumptions!F30 -> 882000
A28: Reviews needing human check | B28: =B27*Assumptions!B32 -> 450 | C28: =C27*Assumptions!C32 -> 5625 | D28: =D27*Assumptions!D32 -> 22680 | E28: =E27*Assumptions!E32 -> 42000 | F28: =F27*Assumptions!F32 -> 70560

Sheet PnL
A1: Profit and loss, cash and runway (INR)
A3: INR | B3: Year 1 | C3: Year 2 | D3: Year 3 | E3: Year 4 | F3: Year 5
A4: Revenue
A5: Institution licences | B5: =Customers!B9*Assumptions!B23*Assumptions!$B$12 -> 200000 | C5: =Customers!C9*Assumptions!C23*Assumptions!$B$12 -> 2175000 | D5: =Customers!D9*Assumptions!D23*Assumptions!$B$12 -> 10350000 | E5: =Customers!E9*Assumptions!E23*Assumptions!$B$12 -> 29000000 | F5: =Customers!F9*Assumptions!F23*Assumptions!$B$12 -> 68200000
A6: Startup/SME hiring packs | B6: =Customers!B16*Assumptions!B24*Assumptions!$B$12 -> 135000 | C6: =Customers!C16*Assumptions!C24*Assumptions!$B$12 -> 1710000 | D6: =Customers!D16*Assumptions!D24*Assumptions!$B$12 -> 7920000 | E6: =Customers!E16*Assumptions!E24*Assumptions!$B$12 -> 21500000 | F6: =Customers!F16*Assumptions!F24*Assumptions!$B$12 -> 49500000
A7: Corporate seasonal plans | B7: =Customers!B23*Assumptions!B25*Assumptions!$B$12 -> 75000 | C7: =Customers!C23*Assumptions!C25*Assumptions!$B$12 -> 1650000 | D7: =Customers!D23*Assumptions!D25*Assumptions!$B$12 -> 8250000 | E7: =Customers!E23*Assumptions!E25*Assumptions!$B$12 -> 24500000 | F7: =Customers!F23*Assumptions!F25*Assumptions!$B$12 -> 58000000
A8: Total revenue | B8: =SUM(B5:B7) -> 410000 | C8: =SUM(C5:C7) -> 5535000 | D8: =SUM(D5:D7) -> 26520000 | E8: =SUM(E5:E7) -> 75000000 | F8: =SUM(F5:F7) -> 175700000
A9: Revenue growth (year on year) | B9: =0 -> 0 | C9: =IF(B8=0,0,C8/B8-1) -> 12.5 | D9: =IF(C8=0,0,D8/C8-1) -> 3.7913279 | E9: =IF(D8=0,0,E8/D8-1) -> 1.8280543 | F9: =IF(E8=0,0,F8/E8-1) -> 1.3426667
A11: Cost of revenue
A12: AI review cost | B12: =Customers!B27*Assumptions!B31 -> 36000 | C12: =Customers!C27*Assumptions!C31 -> 300000 | D12: =Customers!D27*Assumptions!D31 -> 1134000 | E12: =Customers!E27*Assumptions!E31 -> 2100000 | F12: =Customers!F27*Assumptions!F31 -> 3969000
A13: Human review cost | B13: =Customers!B28*Assumptions!B33 -> 27000 | C13: =Customers!C28*Assumptions!C33 -> 337500 | D13: =Customers!D28*Assumptions!D33 -> 1134000 | E13: =Customers!E28*Assumptions!E33 -> 2100000 | F13: =Customers!F28*Assumptions!F33 -> 3528000
A14: Storage and video | B14: =Customers!B26*Assumptions!B34 -> 45000 | C14: =Customers!C26*Assumptions!C34 -> 450000 | D14: =Customers!D26*Assumptions!D34 -> 1890000 | E14: =Customers!E26*Assumptions!E34 -> 3500000 | F14: =Customers!F26*Assumptions!F34 -> 5880000
A15: Base infrastructure | B15: =Assumptions!B35 -> 150000 | C15: =Assumptions!C35 -> 300000 | D15: =Assumptions!D35 -> 800000 | E15: =Assumptions!E35 -> 1500000 | F15: =Assumptions!F35 -> 2500000
A16: Payment and collection costs | B16: =B8*Assumptions!B36 -> 8200 | C16: =C8*Assumptions!C36 -> 110700 | D16: =D8*Assumptions!D36 -> 530400 | E16: =E8*Assumptions!E36 -> 1500000 | F16: =F8*Assumptions!F36 -> 3514000
A17: Total cost of revenue | B17: =SUM(B12:B16) -> 266200 | C17: =SUM(C12:C16) -> 1498200 | D17: =SUM(D12:D16) -> 5488400 | E17: =SUM(E12:E16) -> 10700000 | F17: =SUM(F12:F16) -> 19391000
A18: Gross profit | B18: =B8-B17 -> 143800 | C18: =C8-C17 -> 4036800 | D18: =D8-D17 -> 21031600 | E18: =E8-E17 -> 64300000 | F18: =F8-F17 -> 156309000
A19: Gross margin | B19: =IF(B8=0,0,B18/B8) -> 0.35073171 | C19: =IF(C8=0,0,C18/C8) -> 0.72932249 | D19: =IF(D8=0,0,D18/D8) -> 0.79304676 | E19: =IF(E8=0,0,E18/E8) -> 0.85733333 | F19: =IF(F8=0,0,F18/F8) -> 0.88963574
A21: Operating expenses
A22: Founders | B22: =Assumptions!B37*Assumptions!B38 -> 720000 | C22: =Assumptions!C37*Assumptions!C38 -> 1920000 | D22: =Assumptions!D37*Assumptions!D38 -> 2880000 | E22: =Assumptions!E37*Assumptions!E38 -> 3600000 | F22: =Assumptions!F37*Assumptions!F38 -> 4800000
A23: Engineers | B23: =Assumptions!B39*Assumptions!$B$13*Assumptions!B40 -> 1200000 | C23: =Assumptions!C39*Assumptions!$B$13*Assumptions!C40 -> 3600000 | D23: =Assumptions!D39*Assumptions!$B$13*Assumptions!D40 -> 8000000 | E23: =Assumptions!E39*Assumptions!$B$13*Assumptions!E40 -> 16500000 | F23: =Assumptions!F39*Assumptions!$B$13*Assumptions!F40 -> 31200000
A24: Sales, partnerships and customer success | B24: =Assumptions!B41*Assumptions!$B$13*Assumptions!B42 -> 500000 | C24: =Assumptions!C41*Assumptions!$B$13*Assumptions!C42 -> 2400000 | D24: =Assumptions!D41*Assumptions!$B$13*Assumptions!D42 -> 7000000 | E24: =Assumptions!E41*Assumptions!$B$13*Assumptions!E42 -> 14250000 | F24: =Assumptions!F41*Assumptions!$B$13*Assumptions!F42 -> 27200000
A25: Product and design | B25: =Assumptions!B43*Assumptions!$B$13*Assumptions!B44 -> 300000 | C25: =Assumptions!C43*Assumptions!$B$13*Assumptions!C44 -> 700000 | D25: =Assumptions!D43*Assumptions!$B$13*Assumptions!D44 -> 1600000 | E25: =Assumptions!E43*Assumptions!$B$13*Assumptions!E44 -> 3150000 | F25: =Assumptions!F43*Assumptions!$B$13*Assumptions!F44 -> 6000000
A26: Admin, finance and operations | B26: =Assumptions!B45*Assumptions!$B$13 -> 200000 | C26: =Assumptions!C45*Assumptions!$B$13 -> 600000 | D26: =Assumptions!D45*Assumptions!$B$13 -> 1500000 | E26: =Assumptions!E45*Assumptions!$B$13 -> 2800000 | F26: =Assumptions!F45*Assumptions!$B$13 -> 4800000
A27: Total people costs | B27: =SUM(B22:B26) -> 2920000 | C27: =SUM(C22:C26) -> 9220000 | D27: =SUM(D22:D26) -> 20980000 | E27: =SUM(E22:E26) -> 40300000 | F27: =SUM(F22:F26) -> 74000000
A28: Sales and marketing programmes (new customers x programme CAC) | B28: =Customers!B8*Assumptions!B26+Customers!B15*Assumptions!B27+Customers!B22*Assumptions!B28 -> 310000 | C28: =Customers!C8*Assumptions!C26+Customers!C15*Assumptions!C27+Customers!C22*Assumptions!C28 -> 2160000 | D28: =Customers!D8*Assumptions!D26+Customers!D15*Assumptions!D27+Customers!D22*Assumptions!D28 -> 7230000 | E28: =Customers!E8*Assumptions!E26+Customers!E15*Assumptions!E27+Customers!E22*Assumptions!E28 -> 13890000 | F28: =Customers!F8*Assumptions!F26+Customers!F15*Assumptions!F27+Customers!F22*Assumptions!F28 -> 26150000
A29: Legal, compliance and security | B29: =Assumptions!B46 -> 400000 | C29: =Assumptions!C46 -> 800000 | D29: =Assumptions!D46 -> 1500000 | E29: =Assumptions!E46 -> 2500000 | F29: =Assumptions!F46 -> 4000000
A30: Other G&A | B30: =Assumptions!B47 -> 300000 | C30: =Assumptions!C47 -> 800000 | D30: =Assumptions!D47 -> 1800000 | E30: =Assumptions!E47 -> 3000000 | F30: =Assumptions!F47 -> 5500000
A31: Total operating expenses | B31: =B27+B28+B29+B30 -> 3930000 | C31: =C27+C28+C29+C30 -> 12980000 | D31: =D27+D28+D29+D30 -> 31510000 | E31: =E27+E28+E29+E30 -> 59690000 | F31: =F27+F28+F29+F30 -> 109650000
A33: EBITDA | B33: =B18-B31 -> -3786200 | C33: =C18-C31 -> -8943200 | D33: =D18-D31 -> -10478400 | E33: =E18-E31 -> 4610000 | F33: =F18-F31 -> 46659000
A34: EBITDA margin | B34: =IF(B8=0,0,B33/B8) -> -9.2346341 | C34: =IF(C8=0,0,C33/C8) -> -1.6157543 | D34: =IF(D8=0,0,D33/D8) -> -0.39511312 | E34: =IF(E8=0,0,E33/E8) -> 0.061466667 | F34: =IF(F8=0,0,F33/F8) -> 0.26556061
A35: Tax (simplified) | B35: =MAX(0,B33)*Assumptions!$B$51 -> 0 | C35: =MAX(0,C33)*Assumptions!$B$51 -> 0 | D35: =MAX(0,D33)*Assumptions!$B$51 -> 0 | E35: =MAX(0,E33)*Assumptions!$B$51 -> 1152500 | F35: =MAX(0,F33)*Assumptions!$B$51 -> 11664750
A36: Net profit (simplified) | B36: =B33-B35 -> -3786200 | C36: =C33-C35 -> -8943200 | D36: =D33-D35 -> -10478400 | E36: =E33-E35 -> 3457500 | F36: =F33-F35 -> 34994250
A38: Cash and runway
A39: Opening cash | B39: =Assumptions!$B$50 -> 500000 | C39: =B42 -> 26713800 | D39: =C42 -> 17770600 | E39: =D42 -> 7292200 | F39: =E42 -> 10749700
A40: Equity funding received | B40: =Assumptions!B48 -> 30000000 | C40: =Assumptions!C48 -> 0 | D40: =Assumptions!D48 -> 0 | E40: =Assumptions!E48 -> 0 | F40: =Assumptions!F48 -> 0
A41: Operating cash flow (= net profit, simplified) | B41: =B36 -> -3786200 | C41: =C36 -> -8943200 | D41: =D36 -> -10478400 | E41: =E36 -> 3457500 | F41: =F36 -> 34994250
A42: Closing cash | B42: =B39+B40+B41 -> 26713800 | C42: =C39+C40+C41 -> 17770600 | D42: =D39+D40+D41 -> 7292200 | E42: =E39+E40+E41 -> 10749700 | F42: =F39+F40+F41 -> 45743950
A43: Average monthly burn (when EBITDA is negative) | B43: =MAX(0,-B33)/12 -> 315516.67 | C43: =MAX(0,-C33)/12 -> 745266.67 | D43: =MAX(0,-D33)/12 -> 873200 | E43: =MAX(0,-E33)/12 -> 0 | F43: =MAX(0,-F33)/12 -> 0
A44: Runway at start of year (months, if burning) | B44: =IF(B43=0,"n/a",(B39+B40)/B43) -> 96.666843 | C44: =IF(C43=0,"n/a",(C39+C40)/C43) -> 35.844619 | D44: =IF(D43=0,"n/a",(D39+D40)/D43) -> 20.351122 | E44: =IF(E43=0,"n/a",(E39+E40)/E43) -> n/a | F44: =IF(F43=0,"n/a",(F39+F40)/F43) -> n/a
A45: EBITDA positive? (1 = yes) | B45: =IF(B33>0,1,0) -> 0 | C45: =IF(C33>0,1,0) -> 0 | D45: =IF(D33>0,1,0) -> 0 | E45: =IF(E33>0,1,0) -> 1 | F45: =IF(F33>0,1,0) -> 1
...

Sheet UnitEconomics
A1: Unit economics (Year 3 values; assumptions flagged)
A3: Metric | B3: Institution | C3: Startup/SME | D3: Corporate | E3: Note
A4: ARPU, INR per year (Year 3) | B4: =Assumptions!D23*Assumptions!$B$12 -> 180000 | C4: =Assumptions!D24*Assumptions!$B$12 -> 48000 | D4: =Assumptions!D25*Assumptions!$B$12 -> 330000 | E4: From Assumptions, scenario-adjusted.
A5: Gross margin on this segment | B5: 0.75 | C5: 0.8 | D5: 0.8 | E5: Assumption. Compare with blended gross margin on PnL.
A6: Annual churn | B6: =Assumptions!D20 -> 0.1 | C6: =Assumptions!D21 -> 0.4 | D6: =Assumptions!D22 -> 0.25 | E6: From Assumptions.
A7: Customer lifetime cap (years) | B7: 3 | C7: 3 | D7: 3 | E7: Conservative cap on 1 / churn.
A8: Expected lifetime (years) = MIN(1/churn, cap) | B8: =MIN(1/B6,B7) -> 3 | C8: =MIN(1/C6,C7) -> 2.5 | D8: =MIN(1/D6,D7) -> 3
A9: Lifetime value, INR = ARPU x gross margin x lifetime | B9: =B4*B5*B8 -> 405000 | C9: =C4*C5*C8 -> 96000 | D9: =D4*D5*D8 -> 792000
A10: Programme CAC, INR | B10: =Assumptions!D26 -> 50000 | C10: =Assumptions!D27 -> 10000 | D10: =Assumptions!D28 -> 50000 | E10: Excludes salaries.
A11: Sales/CS salary cost per new customer (all segments, equal split), INR | B11: =PnL!$D$24/(Customers!$D$8+Customers!$D$15+Customers!$D$22) -> 21943.574 | C11: =PnL!$D$24/(Customers!$D$8+Customers!$D$15+Customers!$D$22) -> 21943.574 | D11: =PnL!$D$24/(Customers!$D$8+Customers!$D$15+Customers!$D$22) -> 21943.574 | E11: Simplification: equal allocation.
A12: Fully loaded CAC, INR | B12: =B10+B11 -> 71943.574 | C12: =C10+C11 -> 31943.574 | D12: =D10+D11 -> 71943.574
A13: LTV / CAC | B13: =B9/B12 -> 5.6294118 | C13: =C9/C12 -> 3.0052993 | D13: =D9/D12 -> 11.008627 | E13: Rule of thumb: 3x or more is healthy. Hypothesis until measured.
A14: CAC payback (months) = CAC / (ARPU x gross margin / 12) | B14: =B12/(B4*B5/12) -> 6.3949843 | C14: =C12/(C4*C5/12) -> 9.9823668 | D14: =D12/(D4*D5/12) -> 3.2701624

Sheet Scenarios
A1: Scenario snapshot (static values from this model)
A2: Static snapshot: re-run by changing the scenario cell on Assumptions. Values in INR lakh (1 lakh = 100,000).
A4: Conservative
A5: INR lakh | B5: Year 1 | C5: Year 2 | D5: Year 3 | E5: Year 4 | F5: Year 5
A6: Revenue | B6: 2.2 | C6: 25.9 | D6: 119.7 | E6: 337.5 | F6: 790.6
A7: Gross profit | B7: 0.1 | C7: 16.7 | D7: 88.6 | E7: 277.2 | F7: 683
A8: Operating expenses | B8: 29.2 | C8: 89.8 | D8: 205.8 | E8: 380.9 | F8: 689.2
A9: EBITDA | B9: -29.1 | C9: -73.1 | D9: -117.2 | E9: -103.7 | F9: -6.2
A10: Closing cash | B10: 275.9 | C10: 202.8 | D10: 85.6 | E10: -18 | F10: -24.3
A11: First EBITDA-positive year | B11: Beyond Year 5
A12: Lowest closing cash (INR lakh) | B12: -24.3
A14: Base
A15: INR lakh | B15: Year 1 | C15: Year 2 | D15: Year 3 | E15: Year 4 | F15: Year 5
A16: Revenue | B16: 4.1 | C16: 55.4 | D16: 265.2 | E16: 750 | F16: 1757
A17: Gross profit | B17: 1.4 | C17: 40.4 | D17: 210.3 | E17: 643 | F17: 1563.1
A18: Operating expenses | B18: 39.3 | C18: 129.8 | D18: 315.1 | E18: 596.9 | F18: 1096.5
A19: EBITDA | B19: -37.9 | C19: -89.4 | D19: -104.8 | E19: 46.1 | F19: 466.6
A20: Closing cash | B20: 267.1 | C20: 177.7 | D20: 72.9 | E20: 107.5 | F20: 457.4
A21: First EBITDA-positive year | B21: Year 4
A22: Lowest closing cash (INR lakh) | B22: 72.9
A24: Optimistic
A25: INR lakh | B25: Year 1 | C25: Year 2 | D25: Year 3 | E25: Year 4 | F25: Year 5
A26: Revenue | B26: 6.1 | C26: 84.8 | D26: 408.4 | E26: 1155 | F26: 2705.8
A27: Gross profit | B27: 2.9 | C27: 64.9 | D27: 334 | E27: 1009.1 | F27: 2439.4
A28: Operating expenses | B28: 44.9 | C28: 153.6 | D28: 380 | E28: 726.1 | F28: 1339.5
A29: EBITDA | B29: -42 | C29: -88.7 | D29: -46 | E29: 283 | F29: 1099.9
A30: Closing cash | B30: 263 | C30: 174.3 | D30: 128.3 | E30: 340.5 | F30: 1165.4
A31: First EBITDA-positive year | B31: Year 4
A32: Lowest closing cash (INR lakh) | B32: 128.3
